2020-11-04 21:19:24,369 - app.py - <module> - 11 - INFO - Now Starting!
2020-11-04 21:19:24,385 - _internal.py - _log - 113 - INFO -  * Running on http://127.0.0.1:5000/ (Press CTRL+C to quit)
2020-11-04 21:19:55,097 - _internal.py - _log - 113 - INFO - 127.0.0.1 - - [04/Nov/2020 21:19:55] "[37mGET / HTTP/1.1[0m" 200 -
2020-11-04 21:19:55,150 - _internal.py - _log - 113 - INFO - 127.0.0.1 - - [04/Nov/2020 21:19:55] "[33mGET /favicon.ico HTTP/1.1[0m" 404 -
2020-11-04 21:19:57,582 - _internal.py - _log - 113 - INFO - 127.0.0.1 - - [04/Nov/2020 21:19:57] "[37mGET /log HTTP/1.1[0m" 200 -
2020-11-04 21:19:57,620 - _internal.py - _log - 113 - INFO - 127.0.0.1 - - [04/Nov/2020 21:19:57] "[33mGET /favicon.ico HTTP/1.1[0m" 404 -
2020-11-04 21:20:33,768 - route.py - GetRealTimeInfoStuff - 137 - INFO - Get : gaohang
2020-11-04 21:20:33,820 - app.py - log_exception - 1891 - ERROR - Exception on /classpoint/getrealtimeinfo/stuff [GET]
Traceback (most recent call last):
  File "C:\Users\xjhznb\PycharmProjects\untitled1\venv\lib\site-packages\flask\app.py", line 2446, in wsgi_app
    response = self.full_dispatch_request()
  File "C:\Users\xjhznb\PycharmProjects\untitled1\venv\lib\site-packages\flask\app.py", line 1951, in full_dispatch_request
    rv = self.handle_user_exception(e)
  File "C:\Users\xjhznb\PycharmProjects\untitled1\venv\lib\site-packages\flask\app.py", line 1820, in handle_user_exception
    reraise(exc_type, exc_value, tb)
  File "C:\Users\xjhznb\PycharmProjects\untitled1\venv\lib\site-packages\flask\_compat.py", line 39, in reraise
    raise value
  File "C:\Users\xjhznb\PycharmProjects\untitled1\venv\lib\site-packages\flask\app.py", line 1949, in full_dispatch_request
    rv = self.dispatch_request()
  File "C:\Users\xjhznb\PycharmProjects\untitled1\venv\lib\site-packages\flask\app.py", line 1935, in dispatch_request
    return self.view_functions[rule.endpoint](**req.view_args)
  File "C:\Users\xjhznb\PycharmProjects\untitled1\api_1_0_0\route.py", line 138, in GetRealTimeInfoStuff
    status, current, _next = method.GetRealTimeInfoStuff(stuff_id)
  File "C:\Users\xjhznb\PycharmProjects\untitled1\api_1_0_0\method.py", line 295, in GetRealTimeInfoStuff
    dyndocs = db.GetDynamicCourseInfo(stuff_id=stuff_id, time=time, cnt=2)
  File "C:\Users\xjhznb\PycharmProjects\untitled1\api_1_0_0\database.py", line 45, in GetDynamicCourseInfo
    mydoc = list(mycol.find(query).limit(cnt))
  File "C:\Users\xjhznb\PycharmProjects\untitled1\venv\lib\site-packages\pymongo\cursor.py", line 1156, in next
    if len(self.__data) or self._refresh():
  File "C:\Users\xjhznb\PycharmProjects\untitled1\venv\lib\site-packages\pymongo\cursor.py", line 1073, in _refresh
    self.__send_message(q)
  File "C:\Users\xjhznb\PycharmProjects\untitled1\venv\lib\site-packages\pymongo\cursor.py", line 955, in __send_message
    address=self.__address)
  File "C:\Users\xjhznb\PycharmProjects\untitled1\venv\lib\site-packages\pymongo\mongo_client.py", line 1346, in _run_operation_with_response
    exhaust=exhaust)
  File "C:\Users\xjhznb\PycharmProjects\untitled1\venv\lib\site-packages\pymongo\mongo_client.py", line 1458, in _retryable_read
    exhaust=exhaust) as (sock_info,
  File "D:\python\lib\contextlib.py", line 81, in __enter__
    return next(self.gen)
  File "C:\Users\xjhznb\PycharmProjects\untitled1\venv\lib\site-packages\pymongo\mongo_client.py", line 1282, in _slaveok_for_server
    with self._get_socket(server, session, exhaust=exhaust) as sock_info:
  File "D:\python\lib\contextlib.py", line 81, in __enter__
    return next(self.gen)
  File "C:\Users\xjhznb\PycharmProjects\untitled1\venv\lib\site-packages\pymongo\mongo_client.py", line 1222, in _get_socket
    self.__all_credentials, checkout=exhaust) as sock_info:
  File "D:\python\lib\contextlib.py", line 81, in __enter__
    return next(self.gen)
  File "C:\Users\xjhznb\PycharmProjects\untitled1\venv\lib\site-packages\pymongo\pool.py", line 1138, in get_socket
    sock_info.check_auth(all_credentials)
  File "C:\Users\xjhznb\PycharmProjects\untitled1\venv\lib\site-packages\pymongo\pool.py", line 712, in check_auth
    auth.authenticate(credentials, self)
  File "C:\Users\xjhznb\PycharmProjects\untitled1\venv\lib\site-packages\pymongo\auth.py", line 564, in authenticate
    auth_func(credentials, sock_info)
  File "C:\Users\xjhznb\PycharmProjects\untitled1\venv\lib\site-packages\pymongo\auth.py", line 541, in _authenticate_default
    return _authenticate_scram(credentials, sock_info, 'SCRAM-SHA-1')
  File "C:\Users\xjhznb\PycharmProjects\untitled1\venv\lib\site-packages\pymongo\auth.py", line 263, in _authenticate_scram
    res = sock_info.command(source, cmd)
  File "C:\Users\xjhznb\PycharmProjects\untitled1\venv\lib\site-packages\pymongo\pool.py", line 613, in command
    user_fields=user_fields)
  File "C:\Users\xjhznb\PycharmProjects\untitled1\venv\lib\site-packages\pymongo\network.py", line 167, in command
    parse_write_concern_error=parse_write_concern_error)
  File "C:\Users\xjhznb\PycharmProjects\untitled1\venv\lib\site-packages\pymongo\helpers.py", line 159, in _check_command_response
    raise OperationFailure(msg % errmsg, code, response)
pymongo.errors.OperationFailure: Authentication failed.
2020-11-04 21:20:33,902 - _internal.py - _log - 113 - INFO - 127.0.0.1 - - [04/Nov/2020 21:20:33] "[35m[1mGET /classpoint/getrealtimeinfo/stuff?stuff_id=gaohang HTTP/1.1[0m" 500 -
2020-11-04 21:20:37,220 - _internal.py - _log - 113 - INFO - 127.0.0.1 - - [04/Nov/2020 21:20:37] "[37mGET /log HTTP/1.1[0m" 200 -
2020-11-04 21:21:56,232 - _internal.py - _log - 113 - INFO - 127.0.0.1 - - [04/Nov/2020 21:21:56] "[37mGET /log HTTP/1.1[0m" 200 -
2020-11-04 21:21:59,865 - _internal.py - _log - 113 - INFO - 127.0.0.1 - - [04/Nov/2020 21:21:59] "[37mGET /log HTTP/1.1[0m" 200 -
2020-11-04 21:22:21,351 - route.py - GetRealTimeInfoStuff - 137 - INFO - Get : gaohang
2020-11-04 21:22:21,352 - app.py - log_exception - 1891 - ERROR - Exception on /classpoint/getrealtimeinfo/stuff [GET]
Traceback (most recent call last):
  File "C:\Users\xjhznb\PycharmProjects\untitled1\venv\lib\site-packages\flask\app.py", line 2446, in wsgi_app
    response = self.full_dispatch_request()
  File "C:\Users\xjhznb\PycharmProjects\untitled1\venv\lib\site-packages\flask\app.py", line 1951, in full_dispatch_request
    rv = self.handle_user_exception(e)
  File "C:\Users\xjhznb\PycharmProjects\untitled1\venv\lib\site-packages\flask\app.py", line 1820, in handle_user_exception
    reraise(exc_type, exc_value, tb)
  File "C:\Users\xjhznb\PycharmProjects\untitled1\venv\lib\site-packages\flask\_compat.py", line 39, in reraise
    raise value
  File "C:\Users\xjhznb\PycharmProjects\untitled1\venv\lib\site-packages\flask\app.py", line 1949, in full_dispatch_request
    rv = self.dispatch_request()
  File "C:\Users\xjhznb\PycharmProjects\untitled1\venv\lib\site-packages\flask\app.py", line 1935, in dispatch_request
    return self.view_functions[rule.endpoint](**req.view_args)
  File "C:\Users\xjhznb\PycharmProjects\untitled1\api_1_0_0\route.py", line 138, in GetRealTimeInfoStuff
    status, current, _next = method.GetRealTimeInfoStuff(stuff_id)
  File "C:\Users\xjhznb\PycharmProjects\untitled1\api_1_0_0\method.py", line 295, in GetRealTimeInfoStuff
    dyndocs = db.GetDynamicCourseInfo(stuff_id=stuff_id, time=time, cnt=2)
  File "C:\Users\xjhznb\PycharmProjects\untitled1\api_1_0_0\database.py", line 45, in GetDynamicCourseInfo
    mydoc = list(mycol.find(query).limit(cnt))
  File "C:\Users\xjhznb\PycharmProjects\untitled1\venv\lib\site-packages\pymongo\cursor.py", line 1156, in next
    if len(self.__data) or self._refresh():
  File "C:\Users\xjhznb\PycharmProjects\untitled1\venv\lib\site-packages\pymongo\cursor.py", line 1073, in _refresh
    self.__send_message(q)
  File "C:\Users\xjhznb\PycharmProjects\untitled1\venv\lib\site-packages\pymongo\cursor.py", line 955, in __send_message
    address=self.__address)
  File "C:\Users\xjhznb\PycharmProjects\untitled1\venv\lib\site-packages\pymongo\mongo_client.py", line 1346, in _run_operation_with_response
    exhaust=exhaust)
  File "C:\Users\xjhznb\PycharmProjects\untitled1\venv\lib\site-packages\pymongo\mongo_client.py", line 1458, in _retryable_read
    exhaust=exhaust) as (sock_info,
  File "D:\python\lib\contextlib.py", line 81, in __enter__
    return next(self.gen)
  File "C:\Users\xjhznb\PycharmProjects\untitled1\venv\lib\site-packages\pymongo\mongo_client.py", line 1282, in _slaveok_for_server
    with self._get_socket(server, session, exhaust=exhaust) as sock_info:
  File "D:\python\lib\contextlib.py", line 81, in __enter__
    return next(self.gen)
  File "C:\Users\xjhznb\PycharmProjects\untitled1\venv\lib\site-packages\pymongo\mongo_client.py", line 1222, in _get_socket
    self.__all_credentials, checkout=exhaust) as sock_info:
  File "D:\python\lib\contextlib.py", line 81, in __enter__
    return next(self.gen)
  File "C:\Users\xjhznb\PycharmProjects\untitled1\venv\lib\site-packages\pymongo\pool.py", line 1138, in get_socket
    sock_info.check_auth(all_credentials)
  File "C:\Users\xjhznb\PycharmProjects\untitled1\venv\lib\site-packages\pymongo\pool.py", line 712, in check_auth
    auth.authenticate(credentials, self)
  File "C:\Users\xjhznb\PycharmProjects\untitled1\venv\lib\site-packages\pymongo\auth.py", line 564, in authenticate
    auth_func(credentials, sock_info)
  File "C:\Users\xjhznb\PycharmProjects\untitled1\venv\lib\site-packages\pymongo\auth.py", line 541, in _authenticate_default
    return _authenticate_scram(credentials, sock_info, 'SCRAM-SHA-1')
  File "C:\Users\xjhznb\PycharmProjects\untitled1\venv\lib\site-packages\pymongo\auth.py", line 263, in _authenticate_scram
    res = sock_info.command(source, cmd)
  File "C:\Users\xjhznb\PycharmProjects\untitled1\venv\lib\site-packages\pymongo\pool.py", line 613, in command
    user_fields=user_fields)
  File "C:\Users\xjhznb\PycharmProjects\untitled1\venv\lib\site-packages\pymongo\network.py", line 167, in command
    parse_write_concern_error=parse_write_concern_error)
  File "C:\Users\xjhznb\PycharmProjects\untitled1\venv\lib\site-packages\pymongo\helpers.py", line 159, in _check_command_response
    raise OperationFailure(msg % errmsg, code, response)
pymongo.errors.OperationFailure: Authentication failed.
2020-11-04 21:22:21,353 - _internal.py - _log - 113 - INFO - 127.0.0.1 - - [04/Nov/2020 21:22:21] "[35m[1mGET /classpoint/getrealtimeinfo/stuff?stuff_id=gaohang HTTP/1.1[0m" 500 -
